<?xml version="1.0"?>

<robot name="$(arg ns)" xmlns:xacro="http://ros.org/wiki/xacro">
  <xacro:property name="load" value="$(arg suspended_load)"/>


  <xacro:include filename="$(find simulator)/description/component_snippets.xacro" />
  <!-- Instantiate iris "mechanics" -->
  <xacro:include filename="$(find simulator)/description/iris.xacro" />

  <!-- Instantiate a controller. -->
  <xacro:controller_plugin_macro
    namespace="${namespace}"
    imu_sub_topic="imu"
    >
  </xacro:controller_plugin_macro>

  <!-- Mount an ADIS16448 IMU. -->
  <xacro:imu_plugin_macro
    namespace="${namespace}"
    imu_suffix=""
    parent_link="base_link"
    imu_topic="imu"
    mass_imu_sensor="0.015"
    gyroscope_noise_density="0.0003394"
    gyroscopoe_random_walk="0.000038785"
    gyroscope_bias_correlation_time="1000.0"
    gyroscope_turn_on_bias_sigma="0.0087"
    accelerometer_noise_density="0.004"
    accelerometer_random_walk="0.006"
    accelerometer_bias_correlation_time="300.0"
    accelerometer_turn_on_bias_sigma="0.1960"
  >
    <inertia ixx="0.00001" ixy="0.0" ixz="0.0" iyy="0.00001" iyz="0.0" izz="0.00001" />
    <origin xyz="0 0 0" rpy="0 0 0" />
  </xacro:imu_plugin_macro>

  <xacro:if value="$(arg enable_ground_truth)">
    <!-- Mount an IMU providing ground truth. -->
    <xacro:imu_plugin_macro
      namespace="${namespace}"
      imu_suffix="gt"
      parent_link="base_link"
      imu_topic="ground_truth/imu"
      mass_imu_sensor="0.00001"
      gyroscope_noise_density="0.0"
      gyroscopoe_random_walk="0.0"
      gyroscope_bias_correlation_time="1000.0"
      gyroscope_turn_on_bias_sigma="0.0"
      accelerometer_noise_density="0.0"
      accelerometer_random_walk="0.0"
      accelerometer_bias_correlation_time="300.0"
      accelerometer_turn_on_bias_sigma="0.0"
    >
      <inertia ixx="0.00001" ixy="0.0" ixz="0.0" iyy="0.00001" iyz="0.0" izz="0.00001" />
      <origin xyz="0 0 0" rpy="0 0 0" />
    </xacro:imu_plugin_macro>

    <!-- Mount a generic odometry sensor providing ground truth. -->
    <xacro:odometry_plugin_macro
      namespace="${namespace}/ground_truth"
      odometry_sensor_suffix="gt"
      parent_link="base_link"
      pose_topic="pose"
      pose_with_covariance_topic="pose_with_covariance"
      position_topic="position"
      transform_topic="transform"
      odometry_topic="odometry"
      parent_frame_id="world"
      mass_odometry_sensor="0.00001"
      measurement_divisor="1"
      measurement_delay="0"
      unknown_delay="0.0"
      noise_normal_position="0 0 0"
      noise_normal_quaternion="0 0 0"
      noise_normal_linear_velocity="0 0 0"
      noise_normal_angular_velocity="0 0 0"
      noise_uniform_position="0 0 0"
      noise_uniform_quaternion="0 0 0"
      noise_uniform_linear_velocity="0 0 0"
      noise_uniform_angular_velocity="0 0 0"
      enable_odometry_map="false"
      odometry_map=""
      image_scale=""
    >
      <inertia ixx="0.00001" ixy="0.0" ixz="0.0" iyy="0.00001" iyz="0.0" izz="0.00001" /> <!-- [kg.m^2] [kg.m^2] [kg.m^2] [kg.m^2] [kg.m^2] [kg.m^2] -->
      <origin xyz="0.0 0.0 0.0" rpy="0.0 0.0 0.0" />
    </xacro:odometry_plugin_macro>
  </xacro:if>

  <xacro:if value="$(arg enable_logging)">
    <!-- Instantiate a logger -->
    <xacro:bag_plugin_macro
      namespace="${namespace}"
      bag_file="$(arg log_file)"
      rotor_velocity_slowdown_sim="${rotor_velocity_slowdown_sim}"
    >
    </xacro:bag_plugin_macro>
  </xacro:if>

  <xacro:if value="${load}">

    <joint type="revolute" name="load_rev_1">
      <parent link="base_link"/>
      <child link="${namespace}/load_link_1"/>
      <origin rpy="0.0 0.0 0.0" xyz="0.0 0.0 0.0"/>
      <axis xyz="1 0 0">
      </axis>
      <limit effort="50000" lower="-10000" upper="10000" velocity="10000"/>
    </joint>

    <joint type="revolute" name="load_rev_2">
      <parent link="${namespace}/load_link_1"/>
      <child link="${namespace}/load_link_2"/>
      <origin rpy="0.0 0.0 0.0" xyz="0.0 0.0 0.0"/>
      <axis xyz="0 1 0">
      </axis>
      <limit effort="50000" lower="-10000" upper="10000" velocity="10000"/>
    </joint>

    <joint type="fixed" name="load_joint_final">
      <parent link="${namespace}/load_link_2"/>
      <origin rpy="0.0 0.0 0.0" xyz="0.0 0.0 -$(arg load_link_height)"/>
      <child link="${namespace}/load_link"/>
    </joint>
  
    <link name="${namespace}/load_link_1">
      <inertial>
        <inertia ixx="0.00001" ixy="0.0" ixz="0.0" iyy="0.00001" iyz="0.0" izz="0.00001"/>
        <mass value="0.00005"/>
        <!-- [kg] -->
        <origin rpy="0 0 0" xyz="0 0 0"/>
      </inertial>
      <origin rpy="0 0 0" xyz="0 0 0"/>
    </link>

    <link name="${namespace}/load_link_2">
      <inertial>
        <inertia ixx="0.000000001" ixy="0.0" ixz="0.0" iyy="0.000000001" iyz="0.0" izz="0.000000001"/>
        <mass value="0.00005"/>
        <origin rpy="0 0 0" xyz="0 0 0"/>
      </inertial>
      <origin rpy="0 0 0" xyz="0 0 0"/>
    </link>

    <link name="${namespace}/load_link">
      <inertial>
        <inertia ixx="0.000000001" ixy="0.0" ixz="0.0" iyy="0.000000001" iyz="0.0" izz="0.000000001"/>
        <mass value="$(arg load_mass)"/>
        <!-- [kg] -->
        <origin rpy="0 0 0" xyz="0 0 0"/>
      </inertial>
      <origin rpy="0 0 0" xyz="0 0 0"/>
      <visual name="visual">
        <geometry>
          <box size="0.1 0.1 0.1" />
        </geometry>        
      </visual>
    </link>
    <gazebo reference="${namespace}/load_link">
      <material>Gazebo/Red</material>
    </gazebo>
    <!-- Mount an IMU providing ground truth. -->

    <!-- Mount a generic odometry sensor providing ground truth. -->
    <xacro:odometry_plugin_macro
      namespace="${namespace}/load_pose"
      odometry_sensor_suffix="gt"
      parent_link="${namespace}/load_link"
      pose_topic="pose"
      pose_with_covariance_topic="pose_with_covariance"
      position_topic="position"
      transform_topic="transform"
      odometry_topic="odometry"
      parent_frame_id="world"
      mass_odometry_sensor="0.00001"
      measurement_divisor="1"
      measurement_delay="0"
      unknown_delay="0.0"
      noise_normal_position="0 0 0"
      noise_normal_quaternion="0 0 0"
      noise_normal_linear_velocity="0 0 0"
      noise_normal_angular_velocity="0 0 0"
      noise_uniform_position="0 0 0"
      noise_uniform_quaternion="0 0 0"
      noise_uniform_linear_velocity="0 0 0"
      noise_uniform_angular_velocity="0 0 0"
      enable_odometry_map="false"
      odometry_map=""
      image_scale=""
    >
      <inertia ixx="0.00001" ixy="0.0" ixz="0.0" iyy="0.00001" iyz="0.0" izz="0.00001" /> <!-- [kg.m^2] [kg.m^2] [kg.m^2] [kg.m^2] [kg.m^2] [kg.m^2] -->
      <origin xyz="0.0 0.0 0.0" rpy="0.0 0.0 0.0" />
    </xacro:odometry_plugin_macro>

  </xacro:if>

</robot>

